[2024-07-05T01:36:21.502+0000] {local_task_job_runner.py:120} INFO - ::group::Pre task execution logs
[2024-07-05T01:36:21.539+0000] {taskinstance.py:2076} INFO - Dependencies all met for dep_context=non-requeueable deps ti=<TaskInstance: dag_pipeline.Extraction scheduled__2024-07-04T00:00:00+00:00 [queued]>
[2024-07-05T01:36:21.551+0000] {taskinstance.py:2076} INFO - Dependencies all met for dep_context=requeueable deps ti=<TaskInstance: dag_pipeline.Extraction scheduled__2024-07-04T00:00:00+00:00 [queued]>
[2024-07-05T01:36:21.552+0000] {taskinstance.py:2306} INFO - Starting attempt 1 of 1
[2024-07-05T01:36:21.572+0000] {taskinstance.py:2330} INFO - Executing <Task(_PythonDecoratedOperator): Extraction> on 2024-07-04 00:00:00+00:00
[2024-07-05T01:36:21.584+0000] {standard_task_runner.py:63} INFO - Started process 661 to run task
[2024-07-05T01:36:21.589+0000] {standard_task_runner.py:90} INFO - Running: ['***', 'tasks', 'run', 'dag_pipeline', 'Extraction', 'scheduled__2024-07-04T00:00:00+00:00', '--job-id', '19', '--raw', '--subdir', 'DAGS_FOLDER/dags.py', '--cfg-path', '/tmp/tmp_xp53dp7']
[2024-07-05T01:36:21.590+0000] {standard_task_runner.py:91} INFO - Job 19: Subtask Extraction
[2024-07-05T01:36:21.753+0000] {task_command.py:426} INFO - Running <TaskInstance: dag_pipeline.Extraction scheduled__2024-07-04T00:00:00+00:00 [running]> on host 20b7669a223d
[2024-07-05T01:36:21.943+0000] {taskinstance.py:2648} INFO - Exporting env vars: AIRFLOW_CTX_DAG_OWNER='***' AIRFLOW_CTX_DAG_ID='dag_pipeline' AIRFLOW_CTX_TASK_ID='Extraction' AIRFLOW_CTX_EXECUTION_DATE='2024-07-04T00:00:00+00:00' AIRFLOW_CTX_TRY_NUMBER='1' AIRFLOW_CTX_DAG_RUN_ID='scheduled__2024-07-04T00:00:00+00:00'
[2024-07-05T01:36:21.945+0000] {taskinstance.py:430} INFO - ::endgroup::
[2024-07-05T01:36:21.947+0000] {extract.py:63} INFO - Starting news extraction process
[2024-07-05T01:36:21.977+0000] {connectionpool.py:874} WARNING - Retrying (Retry(total=2, connect=None, read=None, redirect=None, status=None)) after connection broken by 'NameResolutionError("<urllib3.connection.HTTPSConnection object at 0x7fbebae13a10>: Failed to resolve 'www.google.com' ([Errno -2] Name or service not known)")': /search?q=site%3Aeco-business.com+after%3A2022-01-01+PT+Bank+Negara+Indonesia+%28Persero%29+Tbk&num=10
[2024-07-05T01:36:21.984+0000] {connectionpool.py:874} WARNING - Retrying (Retry(total=1, connect=None, read=None, redirect=None, status=None)) after connection broken by 'NameResolutionError("<urllib3.connection.HTTPSConnection object at 0x7fbebae25250>: Failed to resolve 'www.google.com' ([Errno -2] Name or service not known)")': /search?q=site%3Aeco-business.com+after%3A2022-01-01+PT+Bank+Negara+Indonesia+%28Persero%29+Tbk&num=10
[2024-07-05T01:36:21.989+0000] {connectionpool.py:874} WARNING - Retrying (Retry(total=0, connect=None, read=None, redirect=None, status=None)) after connection broken by 'NameResolutionError("<urllib3.connection.HTTPSConnection object at 0x7fbebae25ad0>: Failed to resolve 'www.google.com' ([Errno -2] Name or service not known)")': /search?q=site%3Aeco-business.com+after%3A2022-01-01+PT+Bank+Negara+Indonesia+%28Persero%29+Tbk&num=10
[2024-07-05T01:36:22.001+0000] {taskinstance.py:441} INFO - ::group::Post task execution logs
[2024-07-05T01:36:22.002+0000] {taskinstance.py:2905} ERROR - Task failed with exception
Traceback (most recent call last):
  File "/home/airflow/.local/lib/python3.11/site-packages/urllib3/connection.py", line 198, in _new_conn
    sock = connection.create_connection(
           ^^^^^^^^^^^^^^^^^^^^^^^^^^^^^
  File "/home/airflow/.local/lib/python3.11/site-packages/urllib3/util/connection.py", line 60, in create_connection
    for res in socket.getaddrinfo(host, port, family, socket.SOCK_STREAM):
               ^^^^^^^^^^^^^^^^^^^^^^^^^^^^^^^^^^^^^^^^^^^^^^^^^^^^^^^^^^
  File "/usr/local/lib/python3.11/socket.py", line 962, in getaddrinfo
    for res in _socket.getaddrinfo(host, port, family, type, proto, flags):
               ^^^^^^^^^^^^^^^^^^^^^^^^^^^^^^^^^^^^^^^^^^^^^^^^^^^^^^^^^^^
socket.gaierror: [Errno -2] Name or service not known

The above exception was the direct cause of the following exception:

Traceback (most recent call last):
  File "/home/airflow/.local/lib/python3.11/site-packages/urllib3/connectionpool.py", line 793, in urlopen
    response = self._make_request(
               ^^^^^^^^^^^^^^^^^^^
  File "/home/airflow/.local/lib/python3.11/site-packages/urllib3/connectionpool.py", line 491, in _make_request
    raise new_e
  File "/home/airflow/.local/lib/python3.11/site-packages/urllib3/connectionpool.py", line 467, in _make_request
    self._validate_conn(conn)
  File "/home/airflow/.local/lib/python3.11/site-packages/urllib3/connectionpool.py", line 1099, in _validate_conn
    conn.connect()
  File "/home/airflow/.local/lib/python3.11/site-packages/urllib3/connection.py", line 616, in connect
    self.sock = sock = self._new_conn()
                       ^^^^^^^^^^^^^^^^
  File "/home/airflow/.local/lib/python3.11/site-packages/urllib3/connection.py", line 205, in _new_conn
    raise NameResolutionError(self.host, self, e) from e
urllib3.exceptions.NameResolutionError: <urllib3.connection.HTTPSConnection object at 0x7fbebae26590>: Failed to resolve 'www.google.com' ([Errno -2] Name or service not known)

The above exception was the direct cause of the following exception:

Traceback (most recent call last):
  File "/home/airflow/.local/lib/python3.11/site-packages/requests/adapters.py", line 667, in send
    resp = conn.urlopen(
           ^^^^^^^^^^^^^
  File "/home/airflow/.local/lib/python3.11/site-packages/urllib3/connectionpool.py", line 877, in urlopen
    return self.urlopen(
           ^^^^^^^^^^^^^
  File "/home/airflow/.local/lib/python3.11/site-packages/urllib3/connectionpool.py", line 877, in urlopen
    return self.urlopen(
           ^^^^^^^^^^^^^
  File "/home/airflow/.local/lib/python3.11/site-packages/urllib3/connectionpool.py", line 877, in urlopen
    return self.urlopen(
           ^^^^^^^^^^^^^
  File "/home/airflow/.local/lib/python3.11/site-packages/urllib3/connectionpool.py", line 847, in urlopen
    retries = retries.increment(
              ^^^^^^^^^^^^^^^^^^
  File "/home/airflow/.local/lib/python3.11/site-packages/urllib3/util/retry.py", line 515, in increment
    raise MaxRetryError(_pool, url, reason) from reason  # type: ignore[arg-type]
    ^^^^^^^^^^^^^^^^^^^^^^^^^^^^^^^^^^^^^^^^^^^^^^^^^^^
urllib3.exceptions.MaxRetryError: HTTPSConnectionPool(host='www.google.com', port=443): Max retries exceeded with url: /search?q=site%3Aeco-business.com+after%3A2022-01-01+PT+Bank+Negara+Indonesia+%28Persero%29+Tbk&num=10 (Caused by NameResolutionError("<urllib3.connection.HTTPSConnection object at 0x7fbebae26590>: Failed to resolve 'www.google.com' ([Errno -2] Name or service not known)"))

During handling of the above exception, another exception occurred:

Traceback (most recent call last):
  File "/home/airflow/.local/lib/python3.11/site-packages/airflow/models/taskinstance.py", line 465, in _execute_task
    result = _execute_callable(context=context, **execute_callable_kwargs)
             ^^^^^^^^^^^^^^^^^^^^^^^^^^^^^^^^^^^^^^^^^^^^^^^^^^^^^^^^^^^^^
  File "/home/airflow/.local/lib/python3.11/site-packages/airflow/models/taskinstance.py", line 432, in _execute_callable
    return execute_callable(context=context, **execute_callable_kwargs)
           ^^^^^^^^^^^^^^^^^^^^^^^^^^^^^^^^^^^^^^^^^^^^^^^^^^^^^^^^^^^^
  File "/home/airflow/.local/lib/python3.11/site-packages/airflow/models/baseoperator.py", line 401, in wrapper
    return func(self, *args, **kwargs)
           ^^^^^^^^^^^^^^^^^^^^^^^^^^^
  File "/home/airflow/.local/lib/python3.11/site-packages/airflow/decorators/base.py", line 265, in execute
    return_value = super().execute(context)
                   ^^^^^^^^^^^^^^^^^^^^^^^^
  File "/home/airflow/.local/lib/python3.11/site-packages/airflow/models/baseoperator.py", line 401, in wrapper
    return func(self, *args, **kwargs)
           ^^^^^^^^^^^^^^^^^^^^^^^^^^^
  File "/home/airflow/.local/lib/python3.11/site-packages/airflow/operators/python.py", line 235, in execute
    return_value = self.execute_callable()
                   ^^^^^^^^^^^^^^^^^^^^^^^
  File "/home/airflow/.local/lib/python3.11/site-packages/airflow/operators/python.py", line 252, in execute_callable
    return self.python_callable(*self.op_args, **self.op_kwargs)
           ^^^^^^^^^^^^^^^^^^^^^^^^^^^^^^^^^^^^^^^^^^^^^^^^^^^^^
  File "/opt/airflow/dags/extract.py", line 92, in extract
    response = http.get(GOOGLE, params=params, headers=headers)
               ^^^^^^^^^^^^^^^^^^^^^^^^^^^^^^^^^^^^^^^^^^^^^^^^
  File "/home/airflow/.local/lib/python3.11/site-packages/requests/sessions.py", line 602, in get
    return self.request("GET", url, **kwargs)
           ^^^^^^^^^^^^^^^^^^^^^^^^^^^^^^^^^^
  File "/home/airflow/.local/lib/python3.11/site-packages/requests/sessions.py", line 589, in request
    resp = self.send(prep, **send_kwargs)
           ^^^^^^^^^^^^^^^^^^^^^^^^^^^^^^
  File "/home/airflow/.local/lib/python3.11/site-packages/requests/sessions.py", line 703, in send
    r = adapter.send(request, **kwargs)
        ^^^^^^^^^^^^^^^^^^^^^^^^^^^^^^^
  File "/home/airflow/.local/lib/python3.11/site-packages/requests/adapters.py", line 700, in send
    raise ConnectionError(e, request=request)
requests.exceptions.ConnectionError: HTTPSConnectionPool(host='www.google.com', port=443): Max retries exceeded with url: /search?q=site%3Aeco-business.com+after%3A2022-01-01+PT+Bank+Negara+Indonesia+%28Persero%29+Tbk&num=10 (Caused by NameResolutionError("<urllib3.connection.HTTPSConnection object at 0x7fbebae26590>: Failed to resolve 'www.google.com' ([Errno -2] Name or service not known)"))
[2024-07-05T01:36:22.033+0000] {taskinstance.py:1206} INFO - Marking task as FAILED. dag_id=dag_pipeline, task_id=Extraction, run_id=scheduled__2024-07-04T00:00:00+00:00, execution_date=20240704T000000, start_date=20240705T013621, end_date=20240705T013622
[2024-07-05T01:36:22.051+0000] {standard_task_runner.py:110} ERROR - Failed to execute job 19 for task Extraction (HTTPSConnectionPool(host='www.google.com', port=443): Max retries exceeded with url: /search?q=site%3Aeco-business.com+after%3A2022-01-01+PT+Bank+Negara+Indonesia+%28Persero%29+Tbk&num=10 (Caused by NameResolutionError("<urllib3.connection.HTTPSConnection object at 0x7fbebae26590>: Failed to resolve 'www.google.com' ([Errno -2] Name or service not known)")); 661)
[2024-07-05T01:36:22.083+0000] {local_task_job_runner.py:240} INFO - Task exited with return code 1
[2024-07-05T01:36:22.112+0000] {taskinstance.py:3503} INFO - 0 downstream tasks scheduled from follow-on schedule check
[2024-07-05T01:36:22.123+0000] {local_task_job_runner.py:222} INFO - ::endgroup::
