[2024-07-08T10:01:12.053+0000] {local_task_job_runner.py:120} INFO - ::group::Pre task execution logs
[2024-07-08T10:01:12.114+0000] {taskinstance.py:2076} INFO - Dependencies all met for dep_context=non-requeueable deps ti=<TaskInstance: dag_pipeline.Load manual__2024-07-08T09:59:20.491426+00:00 [queued]>
[2024-07-08T10:01:12.133+0000] {taskinstance.py:2076} INFO - Dependencies all met for dep_context=requeueable deps ti=<TaskInstance: dag_pipeline.Load manual__2024-07-08T09:59:20.491426+00:00 [queued]>
[2024-07-08T10:01:12.134+0000] {taskinstance.py:2306} INFO - Starting attempt 1 of 1
[2024-07-08T10:01:12.164+0000] {taskinstance.py:2330} INFO - Executing <Task(_PythonDecoratedOperator): Load> on 2024-07-08 09:59:20.491426+00:00
[2024-07-08T10:01:12.185+0000] {standard_task_runner.py:63} INFO - Started process 1643 to run task
[2024-07-08T10:01:12.191+0000] {standard_task_runner.py:90} INFO - Running: ['***', 'tasks', 'run', 'dag_pipeline', 'Load', 'manual__2024-07-08T09:59:20.491426+00:00', '--job-id', '74', '--raw', '--subdir', 'DAGS_FOLDER/dags.py', '--cfg-path', '/tmp/tmp5tw1uqc4']
[2024-07-08T10:01:12.193+0000] {standard_task_runner.py:91} INFO - Job 74: Subtask Load
[2024-07-08T10:01:12.306+0000] {task_command.py:426} INFO - Running <TaskInstance: dag_pipeline.Load manual__2024-07-08T09:59:20.491426+00:00 [running]> on host 338dcb453384
[2024-07-08T10:01:12.657+0000] {taskinstance.py:2648} INFO - Exporting env vars: AIRFLOW_CTX_DAG_OWNER='***' AIRFLOW_CTX_DAG_ID='dag_pipeline' AIRFLOW_CTX_TASK_ID='Load' AIRFLOW_CTX_EXECUTION_DATE='2024-07-08T09:59:20.491426+00:00' AIRFLOW_CTX_TRY_NUMBER='1' AIRFLOW_CTX_DAG_RUN_ID='manual__2024-07-08T09:59:20.491426+00:00'
[2024-07-08T10:01:12.660+0000] {taskinstance.py:430} INFO - ::endgroup::
[2024-07-08T10:01:12.670+0000] {logging_mixin.py:188} INFO - An error occurred: connection to server at "localhost" (::1), port 5432 failed: Connection refused
	Is the server running on that host and accepting TCP/IP connections?
connection to server at "localhost" (127.0.0.1), port 5432 failed: Connection refused
	Is the server running on that host and accepting TCP/IP connections?
[2024-07-08T10:01:12.671+0000] {taskinstance.py:441} INFO - ::group::Post task execution logs
[2024-07-08T10:01:12.673+0000] {taskinstance.py:2905} ERROR - Task failed with exception
Traceback (most recent call last):
  File "/home/airflow/.local/lib/python3.11/site-packages/airflow/models/taskinstance.py", line 465, in _execute_task
    result = _execute_callable(context=context, **execute_callable_kwargs)
             ^^^^^^^^^^^^^^^^^^^^^^^^^^^^^^^^^^^^^^^^^^^^^^^^^^^^^^^^^^^^^
  File "/home/airflow/.local/lib/python3.11/site-packages/airflow/models/taskinstance.py", line 432, in _execute_callable
    return execute_callable(context=context, **execute_callable_kwargs)
           ^^^^^^^^^^^^^^^^^^^^^^^^^^^^^^^^^^^^^^^^^^^^^^^^^^^^^^^^^^^^
  File "/home/airflow/.local/lib/python3.11/site-packages/airflow/models/baseoperator.py", line 401, in wrapper
    return func(self, *args, **kwargs)
           ^^^^^^^^^^^^^^^^^^^^^^^^^^^
  File "/home/airflow/.local/lib/python3.11/site-packages/airflow/decorators/base.py", line 265, in execute
    return_value = super().execute(context)
                   ^^^^^^^^^^^^^^^^^^^^^^^^
  File "/home/airflow/.local/lib/python3.11/site-packages/airflow/models/baseoperator.py", line 401, in wrapper
    return func(self, *args, **kwargs)
           ^^^^^^^^^^^^^^^^^^^^^^^^^^^
  File "/home/airflow/.local/lib/python3.11/site-packages/airflow/operators/python.py", line 235, in execute
    return_value = self.execute_callable()
                   ^^^^^^^^^^^^^^^^^^^^^^^
  File "/home/airflow/.local/lib/python3.11/site-packages/airflow/operators/python.py", line 252, in execute_callable
    return self.python_callable(*self.op_args, **self.op_kwargs)
           ^^^^^^^^^^^^^^^^^^^^^^^^^^^^^^^^^^^^^^^^^^^^^^^^^^^^^
  File "/opt/airflow/dags/load.py", line 36, in load_to_postgresql
    cursor.close()
    ^^^^^^
UnboundLocalError: cannot access local variable 'cursor' where it is not associated with a value
[2024-07-08T10:01:12.714+0000] {taskinstance.py:1206} INFO - Marking task as FAILED. dag_id=dag_pipeline, task_id=Load, run_id=manual__2024-07-08T09:59:20.491426+00:00, execution_date=20240708T095920, start_date=20240708T100112, end_date=20240708T100112
[2024-07-08T10:01:12.754+0000] {standard_task_runner.py:110} ERROR - Failed to execute job 74 for task Load (cannot access local variable 'cursor' where it is not associated with a value; 1643)
[2024-07-08T10:01:12.806+0000] {local_task_job_runner.py:240} INFO - Task exited with return code 1
[2024-07-08T10:01:12.863+0000] {taskinstance.py:3503} INFO - 0 downstream tasks scheduled from follow-on schedule check
[2024-07-08T10:01:12.873+0000] {local_task_job_runner.py:222} INFO - ::endgroup::
