[2024-07-08T04:10:12.311+0000] {local_task_job_runner.py:120} INFO - ::group::Pre task execution logs
[2024-07-08T04:10:12.342+0000] {taskinstance.py:2076} INFO - Dependencies all met for dep_context=non-requeueable deps ti=<TaskInstance: dag_pipeline.Transformation scheduled__2024-07-05T00:00:00+00:00 [queued]>
[2024-07-08T04:10:12.355+0000] {taskinstance.py:2076} INFO - Dependencies all met for dep_context=requeueable deps ti=<TaskInstance: dag_pipeline.Transformation scheduled__2024-07-05T00:00:00+00:00 [queued]>
[2024-07-08T04:10:12.356+0000] {taskinstance.py:2306} INFO - Starting attempt 1 of 1
[2024-07-08T04:10:12.373+0000] {taskinstance.py:2330} INFO - Executing <Task(_PythonDecoratedOperator): Transformation> on 2024-07-05 00:00:00+00:00
[2024-07-08T04:10:12.387+0000] {standard_task_runner.py:63} INFO - Started process 94 to run task
[2024-07-08T04:10:12.390+0000] {standard_task_runner.py:90} INFO - Running: ['***', 'tasks', 'run', 'dag_pipeline', 'Transformation', 'scheduled__2024-07-05T00:00:00+00:00', '--job-id', '24', '--raw', '--subdir', 'DAGS_FOLDER/dags.py', '--cfg-path', '/tmp/tmpaw8p_nl1']
[2024-07-08T04:10:12.391+0000] {standard_task_runner.py:91} INFO - Job 24: Subtask Transformation
[2024-07-08T04:10:12.447+0000] {task_command.py:426} INFO - Running <TaskInstance: dag_pipeline.Transformation scheduled__2024-07-05T00:00:00+00:00 [running]> on host 20b7669a223d
[2024-07-08T04:10:12.636+0000] {taskinstance.py:2648} INFO - Exporting env vars: AIRFLOW_CTX_DAG_OWNER='***' AIRFLOW_CTX_DAG_ID='dag_pipeline' AIRFLOW_CTX_TASK_ID='Transformation' AIRFLOW_CTX_EXECUTION_DATE='2024-07-05T00:00:00+00:00' AIRFLOW_CTX_TRY_NUMBER='1' AIRFLOW_CTX_DAG_RUN_ID='scheduled__2024-07-05T00:00:00+00:00'
[2024-07-08T04:10:12.637+0000] {taskinstance.py:430} INFO - ::endgroup::
[2024-07-08T04:10:13.587+0000] {taskinstance.py:441} INFO - ::group::Post task execution logs
[2024-07-08T04:10:13.588+0000] {taskinstance.py:2905} ERROR - Task failed with exception
Traceback (most recent call last):
  File "/home/airflow/.local/lib/python3.11/site-packages/huggingface_hub/utils/_errors.py", line 304, in hf_raise_for_status
    response.raise_for_status()
  File "/home/airflow/.local/lib/python3.11/site-packages/requests/models.py", line 1024, in raise_for_status
    raise HTTPError(http_error_msg, response=self)
requests.exceptions.HTTPError: 401 Client Error: Unauthorized for url: https://huggingface.co/saved_model/resolve/main/tokenizer_config.json

The above exception was the direct cause of the following exception:

Traceback (most recent call last):
  File "/home/airflow/.local/lib/python3.11/site-packages/transformers/utils/hub.py", line 402, in cached_file
    resolved_file = hf_hub_download(
                    ^^^^^^^^^^^^^^^^
  File "/home/airflow/.local/lib/python3.11/site-packages/huggingface_hub/utils/_validators.py", line 114, in _inner_fn
    return fn(*args, **kwargs)
           ^^^^^^^^^^^^^^^^^^^
  File "/home/airflow/.local/lib/python3.11/site-packages/huggingface_hub/file_download.py", line 1221, in hf_hub_download
    return _hf_hub_download_to_cache_dir(
           ^^^^^^^^^^^^^^^^^^^^^^^^^^^^^^
  File "/home/airflow/.local/lib/python3.11/site-packages/huggingface_hub/file_download.py", line 1325, in _hf_hub_download_to_cache_dir
    _raise_on_head_call_error(head_call_error, force_download, local_files_only)
  File "/home/airflow/.local/lib/python3.11/site-packages/huggingface_hub/file_download.py", line 1823, in _raise_on_head_call_error
    raise head_call_error
  File "/home/airflow/.local/lib/python3.11/site-packages/huggingface_hub/file_download.py", line 1722, in _get_metadata_or_catch_error
    metadata = get_hf_file_metadata(url=url, proxies=proxies, timeout=etag_timeout, headers=headers)
               ^^^^^^^^^^^^^^^^^^^^^^^^^^^^^^^^^^^^^^^^^^^^^^^^^^^^^^^^^^^^^^^^^^^^^^^^^^^^^^^^^^^^^
  File "/home/airflow/.local/lib/python3.11/site-packages/huggingface_hub/utils/_validators.py", line 114, in _inner_fn
    return fn(*args, **kwargs)
           ^^^^^^^^^^^^^^^^^^^
  File "/home/airflow/.local/lib/python3.11/site-packages/huggingface_hub/file_download.py", line 1645, in get_hf_file_metadata
    r = _request_wrapper(
        ^^^^^^^^^^^^^^^^^
  File "/home/airflow/.local/lib/python3.11/site-packages/huggingface_hub/file_download.py", line 372, in _request_wrapper
    response = _request_wrapper(
               ^^^^^^^^^^^^^^^^^
  File "/home/airflow/.local/lib/python3.11/site-packages/huggingface_hub/file_download.py", line 396, in _request_wrapper
    hf_raise_for_status(response)
  File "/home/airflow/.local/lib/python3.11/site-packages/huggingface_hub/utils/_errors.py", line 352, in hf_raise_for_status
    raise RepositoryNotFoundError(message, response) from e
huggingface_hub.utils._errors.RepositoryNotFoundError: 401 Client Error. (Request ID: Root=1-668b66a6-365b458e230be4b734285278;7e3d779d-464b-48f8-9ed0-17fbcaa0a130)

Repository Not Found for url: https://huggingface.co/saved_model/resolve/main/tokenizer_config.json.
Please make sure you specified the correct `repo_id` and `repo_type`.
If you are trying to access a private or gated repo, make sure you are authenticated.
Invalid username or password.

The above exception was the direct cause of the following exception:

Traceback (most recent call last):
  File "/home/airflow/.local/lib/python3.11/site-packages/airflow/models/taskinstance.py", line 465, in _execute_task
    result = _execute_callable(context=context, **execute_callable_kwargs)
             ^^^^^^^^^^^^^^^^^^^^^^^^^^^^^^^^^^^^^^^^^^^^^^^^^^^^^^^^^^^^^
  File "/home/airflow/.local/lib/python3.11/site-packages/airflow/models/taskinstance.py", line 432, in _execute_callable
    return execute_callable(context=context, **execute_callable_kwargs)
           ^^^^^^^^^^^^^^^^^^^^^^^^^^^^^^^^^^^^^^^^^^^^^^^^^^^^^^^^^^^^
  File "/home/airflow/.local/lib/python3.11/site-packages/airflow/models/baseoperator.py", line 401, in wrapper
    return func(self, *args, **kwargs)
           ^^^^^^^^^^^^^^^^^^^^^^^^^^^
  File "/home/airflow/.local/lib/python3.11/site-packages/airflow/decorators/base.py", line 265, in execute
    return_value = super().execute(context)
                   ^^^^^^^^^^^^^^^^^^^^^^^^
  File "/home/airflow/.local/lib/python3.11/site-packages/airflow/models/baseoperator.py", line 401, in wrapper
    return func(self, *args, **kwargs)
           ^^^^^^^^^^^^^^^^^^^^^^^^^^^
  File "/home/airflow/.local/lib/python3.11/site-packages/airflow/operators/python.py", line 235, in execute
    return_value = self.execute_callable()
                   ^^^^^^^^^^^^^^^^^^^^^^^
  File "/home/airflow/.local/lib/python3.11/site-packages/airflow/operators/python.py", line 252, in execute_callable
    return self.python_callable(*self.op_args, **self.op_kwargs)
           ^^^^^^^^^^^^^^^^^^^^^^^^^^^^^^^^^^^^^^^^^^^^^^^^^^^^^
  File "/opt/airflow/dags/transform.py", line 10, in sentiment_analysis
    tokenizer_sentiment = AutoTokenizer.from_pretrained("saved_model")
                          ^^^^^^^^^^^^^^^^^^^^^^^^^^^^^^^^^^^^^^^^^^^^
  File "/home/airflow/.local/lib/python3.11/site-packages/transformers/models/auto/tokenization_auto.py", line 826, in from_pretrained
    tokenizer_config = get_tokenizer_config(pretrained_model_name_or_path, **kwargs)
                       ^^^^^^^^^^^^^^^^^^^^^^^^^^^^^^^^^^^^^^^^^^^^^^^^^^^^^^^^^^^^^
  File "/home/airflow/.local/lib/python3.11/site-packages/transformers/models/auto/tokenization_auto.py", line 658, in get_tokenizer_config
    resolved_config_file = cached_file(
                           ^^^^^^^^^^^^
  File "/home/airflow/.local/lib/python3.11/site-packages/transformers/utils/hub.py", line 425, in cached_file
    raise EnvironmentError(
OSError: saved_model is not a local folder and is not a valid model identifier listed on 'https://huggingface.co/models'
If this is a private repository, make sure to pass a token having permission to this repo either by logging in with `huggingface-cli login` or by passing `token=<your_token>`
[2024-07-08T04:10:13.602+0000] {taskinstance.py:1206} INFO - Marking task as FAILED. dag_id=dag_pipeline, task_id=Transformation, run_id=scheduled__2024-07-05T00:00:00+00:00, execution_date=20240705T000000, start_date=20240708T041012, end_date=20240708T041013
[2024-07-08T04:10:13.635+0000] {standard_task_runner.py:110} ERROR - Failed to execute job 24 for task Transformation (saved_model is not a local folder and is not a valid model identifier listed on 'https://huggingface.co/models'
If this is a private repository, make sure to pass a token having permission to this repo either by logging in with `huggingface-cli login` or by passing `token=<your_token>`; 94)
[2024-07-08T04:10:13.691+0000] {local_task_job_runner.py:240} INFO - Task exited with return code 1
[2024-07-08T04:10:13.711+0000] {taskinstance.py:3503} INFO - 0 downstream tasks scheduled from follow-on schedule check
[2024-07-08T04:10:13.714+0000] {local_task_job_runner.py:222} INFO - ::endgroup::
