[2024-07-09T01:37:01.899+0000] {local_task_job_runner.py:120} INFO - ::group::Pre task execution logs
[2024-07-09T01:37:01.989+0000] {taskinstance.py:2076} INFO - Dependencies all met for dep_context=non-requeueable deps ti=<TaskInstance: dag_pipeline.Load manual__2024-07-09T01:35:33.112151+00:00 [queued]>
[2024-07-09T01:37:02.010+0000] {taskinstance.py:2076} INFO - Dependencies all met for dep_context=requeueable deps ti=<TaskInstance: dag_pipeline.Load manual__2024-07-09T01:35:33.112151+00:00 [queued]>
[2024-07-09T01:37:02.012+0000] {taskinstance.py:2306} INFO - Starting attempt 1 of 1
[2024-07-09T01:37:02.041+0000] {taskinstance.py:2330} INFO - Executing <Task(_PythonDecoratedOperator): Load> on 2024-07-09 01:35:33.112151+00:00
[2024-07-09T01:37:02.058+0000] {standard_task_runner.py:63} INFO - Started process 185 to run task
[2024-07-09T01:37:02.062+0000] {standard_task_runner.py:90} INFO - Running: ['airflow', 'tasks', 'run', 'dag_pipeline', 'Load', 'manual__2024-07-09T01:35:33.112151+00:00', '--job-id', '8', '--raw', '--subdir', 'DAGS_FOLDER/dags.py', '--cfg-path', '/tmp/tmp1_5cef_9']
[2024-07-09T01:37:02.063+0000] {standard_task_runner.py:91} INFO - Job 8: Subtask Load
[2024-07-09T01:37:02.260+0000] {task_command.py:426} INFO - Running <TaskInstance: dag_pipeline.Load manual__2024-07-09T01:35:33.112151+00:00 [running]> on host 2a22a675a9f6
[2024-07-09T01:37:02.712+0000] {taskinstance.py:2648} INFO - Exporting env vars: AIRFLOW_CTX_DAG_OWNER='airflow' AIRFLOW_CTX_DAG_ID='dag_pipeline' AIRFLOW_CTX_TASK_ID='Load' AIRFLOW_CTX_EXECUTION_DATE='2024-07-09T01:35:33.112151+00:00' AIRFLOW_CTX_TRY_NUMBER='1' AIRFLOW_CTX_DAG_RUN_ID='manual__2024-07-09T01:35:33.112151+00:00'
[2024-07-09T01:37:02.714+0000] {taskinstance.py:430} INFO - ::endgroup::
[2024-07-09T01:37:02.718+0000] {logging_mixin.py:188} INFO - An error occurred: connection to server at "localhost" (::1), port 5432 failed: Connection refused
	Is the server running on that host and accepting TCP/IP connections?
connection to server at "localhost" (127.0.0.1), port 5432 failed: Connection refused
	Is the server running on that host and accepting TCP/IP connections?
[2024-07-09T01:37:02.721+0000] {python.py:237} INFO - Done. Returned value was: None
[2024-07-09T01:37:02.722+0000] {taskinstance.py:441} INFO - ::group::Post task execution logs
[2024-07-09T01:37:02.791+0000] {taskinstance.py:1206} INFO - Marking task as SUCCESS. dag_id=dag_pipeline, task_id=Load, run_id=manual__2024-07-09T01:35:33.112151+00:00, execution_date=20240709T013533, start_date=20240709T013701, end_date=20240709T013702
[2024-07-09T01:37:02.838+0000] {local_task_job_runner.py:240} INFO - Task exited with return code 0
[2024-07-09T01:37:02.916+0000] {taskinstance.py:3503} INFO - 0 downstream tasks scheduled from follow-on schedule check
[2024-07-09T01:37:02.919+0000] {local_task_job_runner.py:222} INFO - ::endgroup::
