[2024-07-08T10:10:52.278+0000] {local_task_job_runner.py:120} INFO - ::group::Pre task execution logs
[2024-07-08T10:10:52.306+0000] {taskinstance.py:2076} INFO - Dependencies all met for dep_context=non-requeueable deps ti=<TaskInstance: dag_pipeline.Load manual__2024-07-08T10:10:30.926148+00:00 [queued]>
[2024-07-08T10:10:52.317+0000] {taskinstance.py:2076} INFO - Dependencies all met for dep_context=requeueable deps ti=<TaskInstance: dag_pipeline.Load manual__2024-07-08T10:10:30.926148+00:00 [queued]>
[2024-07-08T10:10:52.318+0000] {taskinstance.py:2306} INFO - Starting attempt 1 of 1
[2024-07-08T10:10:52.336+0000] {taskinstance.py:2330} INFO - Executing <Task(_PythonDecoratedOperator): Load> on 2024-07-08 10:10:30.926148+00:00
[2024-07-08T10:10:52.349+0000] {standard_task_runner.py:63} INFO - Started process 1945 to run task
[2024-07-08T10:10:52.353+0000] {standard_task_runner.py:90} INFO - Running: ['***', 'tasks', 'run', 'dag_pipeline', 'Load', 'manual__2024-07-08T10:10:30.926148+00:00', '--job-id', '80', '--raw', '--subdir', 'DAGS_FOLDER/dags.py', '--cfg-path', '/tmp/tmpomw7gioq']
[2024-07-08T10:10:52.355+0000] {standard_task_runner.py:91} INFO - Job 80: Subtask Load
[2024-07-08T10:10:52.407+0000] {task_command.py:426} INFO - Running <TaskInstance: dag_pipeline.Load manual__2024-07-08T10:10:30.926148+00:00 [running]> on host 338dcb453384
[2024-07-08T10:10:52.605+0000] {taskinstance.py:2648} INFO - Exporting env vars: AIRFLOW_CTX_DAG_OWNER='***' AIRFLOW_CTX_DAG_ID='dag_pipeline' AIRFLOW_CTX_TASK_ID='Load' AIRFLOW_CTX_EXECUTION_DATE='2024-07-08T10:10:30.926148+00:00' AIRFLOW_CTX_TRY_NUMBER='1' AIRFLOW_CTX_DAG_RUN_ID='manual__2024-07-08T10:10:30.926148+00:00'
[2024-07-08T10:10:52.607+0000] {taskinstance.py:430} INFO - ::endgroup::
[2024-07-08T10:10:52.610+0000] {logging_mixin.py:188} INFO - An error occurred: connection to server at "localhost" (::1), port 5432 failed: Connection refused
	Is the server running on that host and accepting TCP/IP connections?
connection to server at "localhost" (127.0.0.1), port 5432 failed: Connection refused
	Is the server running on that host and accepting TCP/IP connections?
[2024-07-08T10:10:52.611+0000] {python.py:237} INFO - Done. Returned value was: None
[2024-07-08T10:10:52.611+0000] {taskinstance.py:441} INFO - ::group::Post task execution logs
[2024-07-08T10:10:52.622+0000] {taskinstance.py:1206} INFO - Marking task as SUCCESS. dag_id=dag_pipeline, task_id=Load, run_id=manual__2024-07-08T10:10:30.926148+00:00, execution_date=20240708T101030, start_date=20240708T101052, end_date=20240708T101052
[2024-07-08T10:10:52.661+0000] {local_task_job_runner.py:240} INFO - Task exited with return code 0
[2024-07-08T10:10:52.681+0000] {taskinstance.py:3503} INFO - 0 downstream tasks scheduled from follow-on schedule check
[2024-07-08T10:10:52.685+0000] {local_task_job_runner.py:222} INFO - ::endgroup::
